<?xml version="1.0"?>
<robot name="manipulator">

  <!-- Material Definitions for RViz -->
  <material name="white"><color rgba="1 1 1 1"/></material>
  <material name="blue"><color rgba="0.2 0.2 1 1"/></material>
  <material name="grey"><color rgba="0.5 0.5 0.5 1"/></material>

  <link name="world" />

  <joint name="world_joint" type="fixed">
    <parent link="world"/>
    <child link="link_1"/>
    <origin xyz="0 0 0" rpy="0 0 0"/>
  </joint>

  <!-- Links -->
  <link name="link_1">
    <visual>
      <geometry>
        <mesh filename="package://manipulator/meshes/link_1.stl" scale="0.001 0.001 0.001"/>
      </geometry>
    </visual>

    <collision>
      <geometry>
        <mesh filename="package://manipulator/meshes/link_1.stl" scale="0.001 0.001 0.001"/>
      </geometry>
    </collision>

    <inertial>
      <mass value="0.01"/>
      <origin xyz="0.04 0.00 0.00" rpy="0 0 0"/>
      <inertia ixx="1e-6" ixy="0.0" ixz="0.0" iyy="1e-6" iyz="0.0" izz="1e-6"/>
    </inertial>
  </link>

  <link name="link_2">
    <visual>
      <geometry>
        <mesh filename="package://manipulator/meshes/link_2.stl" scale="0.001 0.001 0.001"/>
      </geometry>
    </visual>

    <collision>
      <geometry>
        <mesh filename="package://manipulator/meshes/link_2.stl" scale="0.001 0.001 0.001"/>
      </geometry>
    </collision>

    <inertial>
      <mass value="0.06"/>
      <origin xyz="0.00 0.00 0.01" rpy="0 0 0"/>
      <inertia ixx="1e-6" ixy="0.0" ixz="0.0" iyy="1e-6" iyz="0.0" izz="1e-6"/>
    </inertial>
  </link>

  <link name="link_3">
    <visual>
      <geometry>
        <mesh filename="package://manipulator/meshes/link_3.stl" scale="0.001 0.001 0.001"/>
      </geometry>
    </visual>

    <collision>
      <geometry>
        <mesh filename="package://manipulator/meshes/link_3.stl" scale="0.001 0.001 0.001"/>
      </geometry>
    </collision>

    <inertial>
      <mass value="0.08"/>
      <origin xyz="-0.04 0.00 0.00" rpy="0 0 0"/>
      <inertia ixx="1e-6" ixy="0.0" ixz="0.0" iyy="1e-6" iyz="0.0" izz="1e-6"/>
    </inertial>
  </link>

  <link name="link_4">
    <visual>
      <geometry>
        <mesh filename="package://manipulator/meshes/link_4.stl" scale="0.001 0.001 0.001"/>
      </geometry>
    </visual>

    <collision>
      <geometry>
        <mesh filename="package://manipulator/meshes/link_4.stl" scale="0.001 0.001 0.001"/>
      </geometry>
    </collision>

    <inertial>
      <mass value="0.07"/>
      <origin xyz="0.02 0.00 0.03" rpy="0 0 0"/>
      <inertia ixx="1e-6" ixy="0.0" ixz="0.0" iyy="1e-6" iyz="0.0" izz="1e-6"/>
    </inertial>
  </link>

  <link name="link_5">
    <visual>
      <geometry>
        <mesh filename="package://manipulator/meshes/link_5.stl" scale="0.001 0.001 0.001"/>
      </geometry>
    </visual>

    <collision>
      <geometry>
        <mesh filename="package://manipulator/meshes/link_5.stl" scale="0.001 0.001 0.001"/>
      </geometry>
    </collision>

    <inertial>
      <mass value="0.03"/>
      <origin xyz="0.00 0.00 0.00" rpy="0 0 0"/>
      <inertia ixx="1e-6" ixy="0.0" ixz="0.0" iyy="1e-6" iyz="0.0" izz="1e-6"/>
    </inertial>
  </link>

  <link name="link_6">
    <visual>
      <geometry>
        <mesh filename="package://manipulator/meshes/link_6.stl" scale="0.001 0.001 0.001"/>
      </geometry>
    </visual>

    <collision>
      <geometry>
        <mesh filename="package://manipulator/meshes/link_6.stl" scale="0.001 0.001 0.001"/>
      </geometry>
    </collision>

    <inertial>
      <mass value="0.01"/>
      <origin xyz="0.01 0.01 0.00" rpy="0 0 0"/>
      <inertia ixx="1e-6" ixy="0.0" ixz="0.0" iyy="1e-6" iyz="0.0" izz="1e-6"/>
    </inertial>
  </link>

  <link name="link_7">
    <visual>
      <geometry>
        <mesh filename="package://manipulator/meshes/link_7.stl" scale="0.001 0.001 0.001"/>
      </geometry>
    </visual>

    <collision>
      <geometry>
        <mesh filename="package://manipulator/meshes/link_7.stl" scale="0.001 0.001 0.001"/>
      </geometry>
    </collision>

    <inertial>
      <mass value="0.01"/>
      <origin xyz="0.01 -0.01 0.00" rpy="0 0 0"/>
      <inertia ixx="1e-6" ixy="0.0" ixz="0.0" iyy="1e-6" iyz="0.0" izz="1e-6"/>
    </inertial>
  </link>

  <!-- Joints -->
  <joint name="joint_1" type="revolute">
    <parent link="link_1"/>
    <child link="link_2"/>
    <origin xyz="0 0 0.043" rpy="0 0 0"/>
    <axis xyz="0 0 1"/>
    <limit lower="-1.5708" upper="1.5708" effort="100" velocity="1"/>
  </joint>

  <joint name="joint_2" type="revolute">
    <parent link="link_2"/>
    <child link="link_3"/>
    <origin xyz="0 0 0.0325" rpy="0 0 0"/>
    <axis xyz="0 1 0"/>
    <limit lower="0" upper="3.14" effort="100" velocity="1"/>
  </joint>

  <joint name="joint_3" type="revolute">
    <parent link="link_3"/>
    <child link="link_4"/>
    <origin xyz="-0.09 0 0" rpy="0 0 0"/>
    <axis xyz="0 1 0"/>
    <limit lower="-3.14" upper="0" effort="100" velocity="1"/>
  </joint>

  <joint name="joint_4" type="revolute">
    <parent link="link_4"/>
    <child link="link_5"/>
    <origin xyz="0.0827 0 0.0355" rpy="0 0 0"/>
    <axis xyz="0 1 0"/>
    <limit lower="-1.5708" upper="1.5708" effort="100" velocity="1"/>
  </joint>

  <joint name="joint_5_left" type="prismatic">
    <parent link="link_5"/>
    <child link="link_6"/>
    <origin xyz="0.019 0.00 0" rpy="0 0 0"/>
    <axis xyz="0 1 0"/>
    <limit lower="0" upper="0.008" effort="100" velocity="1"/>
  </joint>

  <joint name="joint_5_right" type="prismatic">
    <parent link="link_5"/>
    <child link="link_7"/>
    <origin xyz="0.019 0.00 0" rpy="0 0 0"/>
    <axis xyz="0 -1 0"/>
    <limit lower="0" upper="0.008" effort="100" velocity="1"/>
    <mimic joint="joint_5_left" multiplier="1" offset="0"/>
  </joint>

  <!-- Gazebo Material Definitions -->
  <gazebo reference="link_1">
    <material>Gazebo/Grey</material>
  </gazebo>
  <gazebo reference="link_2">
    <material>Gazebo/Blue</material>
  </gazebo>
  <gazebo reference="link_3">
    <material>Gazebo/Grey</material>
  </gazebo>
  <gazebo reference="link_4">
    <material>Gazebo/Blue</material>
  </gazebo>
  <gazebo reference="link_5">
    <material>Gazebo/Grey</material>
  </gazebo>
  <gazebo reference="link_6">
    <material>Gazebo/White</material>
  </gazebo>
  <gazebo reference="link_7">
    <material>Gazebo/White</material>
  </gazebo>

  <!-- ros2_control -->
  <ros2_control name="GazeboSystem" type="system">
    <hardware>
      <plugin>gazebo_ros2_control/GazeboSystem</plugin>
    </hardware>
    <joint name="joint_1">
      <command_interface name="position">
        <param name="min">-1.5708</param>
        <param name="max">1.5708</param>
      </command_interface>
      <state_interface name="position"/>
      <state_interface name="velocity"/>
    </joint>
    <joint name="joint_2">
      <command_interface name="position">
        <param name="min">0</param>
        <param name="max">3.14</param>
      </command_interface>
      <state_interface name="position"/>
      <state_interface name="velocity"/>
    </joint>
    <joint name="joint_3">
      <command_interface name="position">
        <param name="min">-3.14</param>
        <param name="max">0</param>
      </command_interface>
      <state_interface name="position"/>
      <state_interface name="velocity"/>
    </joint>
    <joint name="joint_4">
      <command_interface name="position">
        <param name="min">-1.5708</param>
        <param name="max">1.5708</param>
      </command_interface>
      <state_interface name="position"/>
      <state_interface name="velocity"/>
    </joint>
    <!-- Gripper joints (joint_5_left, joint_5_right) are not controlled by joint_trajectory_controller in this setup -->
  </ros2_control>

</robot>
